Workbook

Sheet README
A1: Form 1120 — preparation worksheet
A2: JK Accounting Group · a C-corporation return, from the trial balance to the tie-outs
B4: What this is
B5: One workbook per client, per year. Copy it, rename it <Client>-1120-<Year>.xlsx, and fill in only the shaded cells. Everything else computes. It does not file anything and it is not the return — it is the working sheet you prepare FROM, and the record of how each figure was reached.
B7: Fill in the shaded cells only
B8: Input | C8: A figure you type. Shaded, blue text.
B9: Computed | C9: A formula. Leave it alone — overtyping one is how a workbook starts lying.
B10: From another tab | C10: Pulled from elsewhere in this workbook. Green.
B11: CHECK | C11: A tie-out that has not passed. Never file with one showing.
B13: The order of work
B14: 1. 0 · Client | C14: Entity details, and the three toggles that decide whether Schedules L, M-1, M-2 and M-3 are even required. Prior-year carryforwards go here — they are the opening position and nothing else supplies them.
B15: 2. 1 · Trial balance | C15: Paste the year's trial balance and map each account to a destination code. Everything on Page 1 is a SUMIF over this tab, so a mis-mapped account is a wrong return, not a wrong worksheet.
B16: 3. 5 · Investments | C16: Do this BEFORE Schedules C and D if the client holds a brokerage account — it produces the dividend, realized and unrealized figures those tabs need.
B17: 4. 3 · Schedule C | C17: Dividends, and the deduction most easily missed.
B18: 5. 4 · Schedule D | C18: Capital gains and losses, and the loss pool the filed return will not record.
B19: 6. 2 · Page 1 | C19: Income and deductions. Mostly pulls from tabs 1, 3, 4 and 6.
B20: 7. 6 · Schedule J | C20: The tax. Flat 21%, less credits, against payments.
B21: 8. 7–10 · K, L, M-1, M-2 | C21: The questions, the balance sheet, the book-to-tax bridge, retained earnings.
B22: 9. 11 · Tie-outs | C22: Every check in one place. All must pass.
B23: 10. 12 · Carry forward | C23: What next year needs from this year. Fill it in before you close the file.
A25: THREE THINGS THIS WORKSHEET EXISTS TO STOP
B26: The dividends-received deduction that never gets taken | C26: A C-corporation may deduct 50% (or 65%) of dividends from domestic corporations. Schedule C has a catch-all line — Other dividends — that carries no percentage and therefore no deduction, and sending the whole dividend total there is the silent default. Tab 3 will not let it pass unremarked.
B27: A corporate capital loss treated as if it were deductible | C27: It deducts nothing against ordinary income. It carries back 3 years and forward 5 — and Schedule D's carryover line stays BLANK in a year with no gains, so the filed return records the pool nowhere at all. Tab 4 keeps the register; nothing else will.
B28: The Schedule M-1 sign trap | C28: A book unrealized LOSS belongs on line 5; a book unrealized GAIN on line 7. The sign flips between years, so copying last year's placement gives a return that balances internally and is wrong. Tab 9 takes ONE signed figure and puts it on the right line itself.
A30: EXAMPLE — the format expected, NOT anybody's data
B31: Trial-balance row (tab 1)
B32: Account name | C32: Book amount | D32: Map code | E32: Note
B33: Sales | C33: 4,222,429.70 | D33: GROSS_RECEIPTS
B34: Dividend Income | C34: 31,527.68 | D34: DIVIDENDS | E34: from the brokerage JE
B35: Bank Fees & Charges | C35: 12,469.96 | D35: OTHER_DED | E35: investment management fees
B36: Unrealized Gain/Loss | C36: 106,123.84 | D36: NON_TAX | E36: book only — goes to M-1, tab 9
B38: Dates as YYYY-MM-DD · amounts to the cent, no currency symbol typed · a code from the drop-down, never free text.
B40: Before you file
B41: Line numbers last verified against the 2024 forms · 2026-09-09. Re-verify on irs.gov before entering anything. The IRS renumbers, and this firm has been caught by it.
B42: Client figures live in this workbook and in the client's working paper (projects/tax-returns/). They are never committed to the repo. The blank master is; a filled copy is not.
B43: Procedure for the brokerage half: projects/sops/brokerage-investment-accounts.md

Sheet 0-Client
A1: 0 · Client, year and the toggles
A2: Fill this first — three of these cells decide which schedules the return even needs
A4: THE ENTITY
B5: Client legal name
B6: EIN (format 12-3456789)
B7: Tax year (calendar year ending 12/31)
B8: Date incorporated
B9: State of incorporation
B10: Prepared by
B11: Date prepared
B12: Reviewed by
A14: THE TOGGLES — what this return has to carry
B15: Total assets at end of year (Schedule L, tab 8) | C15: ='8-SchL'!$E$24 -> 0
B16: Total receipts for the year (Page 1 line 1c + lines 4 to 10) | C16: ='2-Page1'!$D$8+SUM('2-Page1'!$D$11:$D$17) -> 0
B17: Schedules L, M-1 and M-2 required? | C17: =IF(AND(N('0-Client'!$C$15)<250000,N('0-Client'!$C$16)<250000),"NOT required","REQUIRED") -> NOT required | E17: Schedule K asks this. Both under $250,000 and they may be omitted — but the firm fills them anyway when the client has a real balance sheet.
B18: Schedule M-3 instead of M-1? | C18: =IF(N('0-Client'!$C$15)>=10000000,"M-3 REQUIRED","M-1") -> M-1 | E18: M-3 replaces M-1 at $10 million of total assets. This workbook builds M-1 only.
A20: OPENING POSITION — from LAST year's FILED return, not from the books
B21: Where these differ from QuickBooks, the FILED RETURN governs, and the difference is written into the working paper so nobody re-derives it next year.
B22: Capital-loss pool brought forward
B23: Earliest year in that pool (for the 5-year expiry)
B24: NOL carryforward available
B25: Cumulative unrealized gain/(loss) on investments at 1 Jan
B26: Retained earnings, END of last year, PER THE FILED RETURN
B27: Total assets, END of last year, PER THE FILED RETURN
B28: Federal income tax PAID during the year (estimates + extension)
B29: Overpayment credited forward from last year
A31: THE STANDING WARNING
B32: Line numbers last verified against the 2024 forms · 2026-09-09. Re-verify on irs.gov before entering anything.

Sheet 1-TrialBalance
A1: 1 · Trial balance → where each account goes
A2: Everything on Page 1 is a SUMIF over this tab. A mis-mapped account is a wrong return.
A4: THE MAP CODES
B5: Code | C5: Goes to
B6: GROSS_RECEIPTS | C6: Page 1 line 1a — gross receipts or sales
B7: RETURNS | C7: Page 1 line 1b — returns and allowances
B8: COGS | C8: Page 1 line 2 — cost of goods sold (Form 1125-A)
B9: DIVIDENDS | C9: Page 1 line 4 — via Schedule C (tab 3)
B10: INTEREST | C10: Page 1 line 5 — interest income
B11: GROSS_RENTS | C11: Page 1 line 6
B12: ROYALTIES | C12: Page 1 line 7
B13: CAPGAIN | C13: Page 1 line 8 — via Schedule D (tab 4)
B14: F4797 | C14: Page 1 line 9 — Form 4797
B15: OTHER_INC | C15: Page 1 line 10 — other income (needs a statement)
B16: OFFICER_COMP | C16: Page 1 line 12 — Form 1125-E
... B34: EXCLUDE | C34: Deliberately excluded. Say why in the note.
A36: THE TRIAL BALANCE — paste it here
B37: Sign convention: income and equity POSITIVE as they appear on the P&L; expenses POSITIVE. Page 1 subtracts. Do not enter expenses as negatives.
B38: Account name (as in QuickBooks) | C38: Book amount | D38: Map code | E38: Note — why, if it is not obvious
B119: Total, all rows | C119: =SUM(C39:C118) -> 0 | E119: A trial balance nets to zero only if you entered it as one. This total is a typing check, not a balance check.
B120: Rows with an amount but NO map code | C120: =SUMPRODUCT((C39:C118<>"")*(D39:D118="")) -> 0 | E120: Must be zero. An unmapped amount is simply missing from the return.

Sheet 2-Page1
A1: 2 · Form 1120, page 1
A2: Income, deductions, and the tax. Line numbers last verified against the 2024 forms · 2026-09-09. Re-verify on irs.gov before entering anything.
A4: INCOME
B5: Line | C5: Concept | D5: Amount | E5: Typed? | F5: Where it comes from
B6: 1a | C6: Gross receipts or sales | D6: =SUMIF('1-TrialBalance'!$D$39:$D$118,"GROSS_RECEIPTS",'1-TrialBalance'!$C$39:$C$118) -> 0 | E6: computed | F6: Trial balance · GROSS_RECEIPTS
B7: 1b | C7: Returns and allowances | D7: =SUMIF('1-TrialBalance'!$D$39:$D$118,"RETURNS",'1-TrialBalance'!$C$39:$C$118) -> 0 | E7: computed | F7: Trial balance · RETURNS
B8: 1c | C8: Balance — subtract 1b from 1a | D8: =$D$6-$D$7 -> 0 | E8: computed
B9: 2 | C9: Cost of goods sold (attach Form 1125-A) | D9: =SUMIF('1-TrialBalance'!$D$39:$D$118,"COGS",'1-TrialBalance'!$C$39:$C$118) -> 0 | E9: computed | F9: Trial balance · COGS
B10: 3 | C10: Gross profit | D10: =$D$8-$D$9 -> 0 | E10: computed
B11: 4 | C11: Dividends and inclusions (Schedule C line 23) | D11: ='3-SchC'!$D$42 -> 0 | E11: computed | F11: Tab 3 · Schedule C
B12: 5 | C12: Interest | D12: =SUMIF('1-TrialBalance'!$D$39:$D$118,"INTEREST",'1-TrialBalance'!$C$39:$C$118) -> 0 | E12: computed | F12: Trial balance · INTEREST. A bond or money-market FUND pays dividends, not interest — no 1099-INT is normal
B13: 6 | C13: Gross rents | D13: =SUMIF('1-TrialBalance'!$D$39:$D$118,"GROSS_RENTS",'1-TrialBalance'!$C$39:$C$118) -> 0 | E13: computed | F13: Trial balance · GROSS_RENTS
B14: 7 | C14: Gross royalties | D14: =SUMIF('1-TrialBalance'!$D$39:$D$118,"ROYALTIES",'1-TrialBalance'!$C$39:$C$118) -> 0 | E14: computed | F14: Trial balance · ROYALTIES
B15: 8 | C15: Capital gain net income (attach Schedule D) | D15: ='4-SchD'!$F$30 -> 0 | E15: computed | F15: Tab 4 · Schedule D Part III. A NET LOSS enters here as ZERO
B16: 9 | C16: Net gain or (loss) from Form 4797 | D16: =SUMIF('1-TrialBalance'!$D$39:$D$118,"F4797",'1-TrialBalance'!$C$39:$C$118) -> 0 | E16: computed | F16: Trial balance · F4797
B17: 10 | C17: Other income (attach statement) | D17: =SUMIF('1-TrialBalance'!$D$39:$D$118,"OTHER_INC",'1-TrialBalance'!$C$39:$C$118) -> 0 | E17: computed | F17: Trial balance · OTHER_INC — and the statement has to be drafted
B18: 11 | C18: TOTAL INCOME | D18: =$D$10+SUM($D$11:$D$17) -> 0 | E18: computed
A20: DEDUCTIONS
B21: 12 | C21: Compensation of officers (attach Form 1125-E) | D21: =SUMIF('1-TrialBalance'!$D$39:$D$118,"OFFICER_COMP",'1-TrialBalance'!$C$39:$C$118) -> 0 | E21: computed | F21: Trial balance · OFFICER_COMP
B22: 13 | C22: Salaries and wages (less employment credits) | D22: =SUMIF('1-TrialBalance'!$D$39:$D$118,"SALARIES",'1-TrialBalance'!$C$39:$C$118) -> 0 | E22: computed | F22: Trial balance · SALARIES
B23: 14 | C23: Repairs and maintenance | D23: =SUMIF('1-TrialBalance'!$D$39:$D$118,"REPAIRS",'1-TrialBalance'!$C$39:$C$118) -> 0 | E23: computed | F23: Trial balance · REPAIRS
B24: 15 | C24: Bad debts | D24: =SUMIF('1-TrialBalance'!$D$39:$D$118,"BADDEBT",'1-TrialBalance'!$C$39:$C$118) -> 0 | E24: computed | F24: Trial balance · BADDEBT
B25: 16 | C25: Rents | D25: =SUMIF('1-TrialBalance'!$D$39:$D$118,"RENTS",'1-TrialBalance'!$C$39:$C$118) -> 0 | E25: computed | F25: Trial balance · RENTS
B26: 17 | C26: Taxes and licenses | D26: =SUMIF('1-TrialBalance'!$D$39:$D$118,"TAXES_LIC",'1-TrialBalance'!$C$39:$C$118) -> 0 | E26: computed | F26: Trial balance · TAXES_LIC. ⚠ FEDERAL income tax is NOT deductible — map it FED_TAX
B27: 18 | C27: Interest | D27: =SUMIF('1-TrialBalance'!$D$39:$D$118,"INT_EXP",'1-TrialBalance'!$C$39:$C$118) -> 0 | E27: computed | F27: Trial balance · INT_EXP
B28: 19 | C28: Charitable contributions | D28: =$D$55 -> 0 | E28: computed | F28: LIMITED to 10% — see the limit block at the foot of this tab. The excess carries forward 5 years and the return records it nowhere
B29: 20 | C29: Depreciation from Form 4562 | D29: =SUMIF('1-TrialBalance'!$D$39:$D$118,"DEPREC",'1-TrialBalance'!$C$39:$C$118) -> 0 | E29: computed | F29: Trial balance · DEPREC
B30: 21 | C30: Depletion | D30: =SUMIF('1-TrialBalance'!$D$39:$D$118,"DEPLETION",'1-TrialBalance'!$C$39:$C$118) -> 0 | E30: computed | F30: Trial balance · DEPLETION
B31: 22 | C31: Advertising | D31: =SUMIF('1-TrialBalance'!$D$39:$D$118,"ADVERTISING",'1-TrialBalance'!$C$39:$C$118) -> 0 | E31: computed | F31: Trial balance · ADVERTISING
B32: 23 | C32: Pension, profit-sharing, etc., plans | D32: =SUMIF('1-TrialBalance'!$D$39:$D$118,"PENSION",'1-TrialBalance'!$C$39:$C$118) -> 0 | E32: computed | F32: Trial balance · PENSION
B33: 24 | C33: Employee benefit programs | D33: =SUMIF('1-TrialBalance'!$D$39:$D$118,"BENEFITS",'1-TrialBalance'!$C$39:$C$118) -> 0 | E33: computed | F33: Trial balance · BENEFITS
B34: 25 | C34: Energy efficient commercial buildings deduction | E34: TYPED | F34: Form 7205, if any
B35: 26 | C35: Other deductions (attach statement) | D35: =SUMIF('1-TrialBalance'!$D$39:$D$118,"OTHER_DED",'1-TrialBalance'!$C$39:$C$118) -> 0 | E35: computed | F35: Trial balance · OTHER_DED. Investment management fees belong here — deductible for a CORPORATION (§162); the §67(g) bar is an individual rule
B36: 27 | C36: TOTAL DEDUCTIONS | D36: =SUM($D$21:$D$35) -> 0 | E36: computed
B38: 28 | C38: Taxable income before NOL and special deductions | D38: =$D$18-$D$36 -> 0 | E38: computed
B39: 29a | C39: Net operating loss deduction | E39: TYPED | F39: From tab 0 · NOL carryforward, limited to 80% of line 28 for post-2017 losses — check before entering
B40: 29b | C40: Special deductions (Schedule C line 24) | D40: ='3-SchC'!$F$43 -> 0 | E40: computed | F40: Tab 3 · the dividends-received deduction
B41: 29c | C41: Add lines 29a and 29b | D41: =$D$39+$D$40 -> 0 | E41: computed
B42: 30 | C42: TAXABLE INCOME | D42: =$D$38-$D$41 -> 0 | E42: computed
A44: TAX AND PAYMENTS
...

Sheet 3-SchC
A1: 3 · Schedule C — dividends, and the deduction most easily missed
A2: A C-corporation deducts part of what it receives from DOMESTIC corporations. Line numbers last verified against the 2024 forms · 2026-09-09. Re-verify on irs.gov before entering anything.
A4: BEFORE YOU FILL THE SCHEDULE — decide the deduction
C5: Schedule C has a catch-all line 20, Other dividends. It carries NO percentage and therefore NO deduction. Sending the whole dividend total there is the silent default, and it has already happened on a real filed return. Work these four rows first.
C6: Total ordinary dividends received (1099-DIV box 1a, ALL accounts)
C7: Does any account hold DOMESTIC CORPORATE SHARES? (Yes / No)
C8: Amount confirmed §243 / §854(b) ELIGIBLE by the broker or fund
C9: §246(c) holding period met on that amount? (Yes / No / Not tested)
C10: Of the eligible amount, from payers 20%-or-more owned
C11: Who was asked, when, and what they said
C12: → Eligible at 50% (less-than-20%-owned) | D12: =IF(OR('3-SchC'!$D$9="No",'3-SchC'!$D$9=""),0,MAX(0,N('3-SchC'!$D$8)-N('3-SchC'!$D$10))) -> 0 | F12: Zero until the holding period is answered Yes — deliberately.
C13: → Eligible at 65% (20%-or-more-owned) | D13: =IF(OR('3-SchC'!$D$9="No",'3-SchC'!$D$9=""),0,N('3-SchC'!$D$10)) -> 0
C14: → Everything else — line 20, no deduction | D14: =N('3-SchC'!$D$6)-'3-SchC'!$D$12-'3-SchC'!$D$13 -> 0
C15: VERDICT | D15: =IF(N('3-SchC'!$D$6)=0,"—",IF(AND('3-SchC'!$D$12+'3-SchC'!$D$13=0,'3-SchC'!$D$7="Yes"),"⚠ ALL on line 20 while the client HOLDS domestic shares — ask the broker before filing",IF('3-SchC'!$D$12+'3-SchC'!$D$13=0,"No DRD — reason recorded above","DRD taken — check the reason row is filled in"))) -> —
A17: SCHEDULE C AS IT IS FILLED IN
B18: Line | C18: Concept | D18: (a) Dividends | E18: (b) % | F18: (c) Special deduction | G18: Note
B19: 1 | C19: Dividends from less-than-20%-owned domestic corporations | D19: ='3-SchC'!$D$12 -> 0 | E19: 0.5 | F19: =ROUND(D19*E19,2) -> 0 | G19: 🔴 THE DRD LINE. This is where portfolio dividends from US companies belong.
B20: 2 | C20: Dividends from 20%-or-more-owned domestic corporations | D20: ='3-SchC'!$D$13 -> 0 | E20: 0.65 | F20: =ROUND(D20*E20,2) -> 0
B21: 3 | C21: Dividends on certain debt-financed stock | G21: §246A — only if the shares were bought with borrowed money
B22: 4 | C22: Certain preferred stock of less-than-20%-owned public utilities | E22: 0.233 | F22: =ROUND(D22*E22,2) -> 0
B23: 5 | C23: Certain preferred stock of 20%-or-more-owned public utilities | E23: 0.267 | F23: =ROUND(D23*E23,2) -> 0
B24: 6 | C24: Less-than-20%-owned FOREIGN corporations and certain FSCs | E24: 0.5 | F24: =ROUND(D24*E24,2) -> 0
B25: 7 | C25: 20%-or-more-owned foreign corporations and certain FSCs | E25: 0.65 | F25: =ROUND(D25*E25,2) -> 0
B26: 8 | C26: Wholly owned foreign subsidiaries | E26: 1 | F26: =ROUND(D26*E26,2) -> 0
B27: 9 | C27: Subtotal — add lines 1 through 8 | D27: =SUM(D19:D26) -> 0 | F27: =SUM(F19:F26) -> 0 | G27: See the instructions for the taxable-income limitation
B28: 10 | C28: Dividends from an SBIC | E28: 1 | F28: =ROUND(D28*E28,2) -> 0
B29: 11 | C29: Dividends from affiliated group members | E29: 1 | F29: =ROUND(D29*E29,2) -> 0
B30: 12 | C30: Dividends from certain FSCs | E30: 1 | F30: =ROUND(D30*E30,2) -> 0
B31: 13 | C31: Foreign-source portion from a specified 10%-owned foreign corporation | E31: 1 | F31: =ROUND(D31*E31,2) -> 0 | G31: §245A
B32: 14 | C32: Dividends from foreign corporations not on 3, 6, 7, 8, 11, 12 or 13
B33: 16a | C33: Subpart F inclusions — sale of lower-tier stock (Form 5471) | E33: 1 | F33: =ROUND(D33*E33,2) -> 0
B34: 16b | C34: Subpart F inclusions from hybrid dividends of tiered corporations
B35: 16c | C35: Other subpart F inclusions
B36: 17 | C36: GILTI (Forms 5471 and 8992)
B37: 18 | C37: Gross-up for foreign taxes deemed paid | G37: §78
B38: 19 | C38: IC-DISC and former DISC dividends
B39: 20 | C39: OTHER DIVIDENDS | D39: ='3-SchC'!$D$14 -> 0 | G39: ⚠ No percentage column — nothing entered here earns a deduction
B40: 21 | C40: Deduction for dividends paid on certain preferred stock of public utilities | F40: =0 -> 0
B41: 22 | C41: §250 deduction (Form 8993) | F41: =0 -> 0
B42: 23 | C42: TOTAL DIVIDENDS AND INCLUSIONS → page 1 line 4 | D42: =SUM(D27:D39) -> 0 | G42: Column (a), lines 9 through 20
...

Sheet 4-SchD
A1: 4 · Schedule D — capital gains and losses
A2: A corporation deducts capital losses ONLY against capital gains (§1211(a)). Line numbers last verified against the 2024 forms · 2026-09-09. Re-verify on irs.gov before entering anything.
A4: PART I — SHORT-TERM (Form 8949 Part I)
B5: Line | C5: Concept | D5: (d) Proceeds | E5: (e) Cost basis | F5: (h) Gain / (loss) | G5: Note
B6: 1a | C6: Short-term 1099-B, basis reported, no adjustments | G6: Only if you are NOT using Form 8949 for them
B7: 1b | C7: Totals — Form 8949 Box A | G7: Wash sales are ALREADY inside column (h). Do not adjust again
B8: 2 | C8: Totals — Form 8949 Box B | G8: Basis not reported to the IRS
B9: 3 | C9: Totals — Form 8949 Box C | G9: Not reported on a 1099-B at all
B10: 4 | C10: Short-term gain from installment sales (Form 6252)
B11: 5 | C11: Short-term gain or (loss) from like-kind exchanges (Form 8824)
B12: 6 | C12: Unused capital loss carryover (attach computation) | G12: Only to the extent of gains. In a year with no gains this stays BLANK — which is why the pool has to be tracked outside the return.
B13: 7 | C13: NET SHORT-TERM | D13: =SUM(D6:D9) -> 0 | E13: =SUM(E6:E9) -> 0 | F13: =SUM(F6:F12) -> 0
A15: PART II — LONG-TERM (Form 8949 Part II)
B16: Line | C16: Concept | D16: (d) Proceeds | E16: (e) Cost basis | F16: (h) Gain / (loss) | G16: Note
B17: 8a | C17: Long-term 1099-B, basis reported, no adjustments
B18: 8b | C18: Totals — Form 8949 Box D
B19: 9 | C19: Totals — Form 8949 Box E
B20: 10 | C20: Totals — Form 8949 Box F
B21: 11 | C21: Gain from Form 4797
B22: 12 | C22: Long-term gain from installment sales
B23: 13 | C23: Long-term gain or (loss) from like-kind exchanges
B24: 14 | C24: CAPITAL GAIN DISTRIBUTIONS (1099-DIV box 2a) | G24: 🔑 ALWAYS long-term, however long the fund was held — and they are NOT dividends. Take them OUT of Schedule C
B25: 15 | C25: NET LONG-TERM | D25: =SUM(D17:D20) -> 0 | E25: =SUM(E17:E20) -> 0 | F25: =SUM(F17:F24) -> 0
A27: PART III — SUMMARY
B28: 16 | C28: Excess of net short-term gain over net long-term loss | F28: =IF(AND(F13>0,F25<0),MAX(0,F13+F25),0) -> 0
B29: 17 | C29: Net capital gain — excess of net long-term gain over net short-term loss | F29: =IF(AND(F25>0,F13<0),MAX(0,F13+F25),IF(AND(F25>0,F13>=0),F25,0)) -> 0
B30: 18 | C30: TOTAL → page 1 line 8 | F30: =MAX(0,F13+F25) -> 0 | G30: 🛑 Floored at ZERO. A net capital loss puts NOTHING on page 1.
A32: THE NET POSITION, AND THE POOL NOTHING ELSE RECORDS
C33: Net capital gain / (loss) for the year | F33: =F13+F25 -> 0
C34: Of which DEDUCTIBLE this year | F34: =MAX(0,F13+F25) -> 0 | G34: A loss deducts nothing. §1211(a).
C35: NOT deductible — goes to Schedule M-1 line 3 | F35: =MAX(0,-(F13+F25)) -> 0 | G35: Tab 9 picks this up automatically.
C37: Pool brought forward from prior years | F37: ='0-Client'!$C$22 -> 0
C38: Used this year against gains | F38: =MIN(N('0-Client'!$C$22),MAX(0,F13+F25)) -> 0 | G38: Enter this on line 6 above — and ONLY this much.
C39: Added this year | F39: =MAX(0,-(F13+F25)) -> 0
C40: POOL CARRIED FORWARD | F40: =N('0-Client'!$C$22)-$F$38+MAX(0,-(F13+F25)) -> 0 | G40: 🛑 Carry it to tab 12. Line 6 is BLANK in a year with no gains, so the filed return records this pool NOWHERE. Back 3 years, forward 5; short-term when used.
C41: Earliest year in the pool → expires after | F41: =IF(N('0-Client'!$C$23)=0,"—",N('0-Client'!$C$23)+5) -> —

Sheet 5-Investments
A1: 5 · Brokerage accounts — the year-end split
A2: Procedure: projects/sops/brokerage-investment-accounts.md · do this BEFORE tabs 3 and 4
B4: The books carry the account at MARKET value, so the monthly entry's balancing line absorbs REALIZED and UNREALIZED movement in one number — and only one of the two is taxable. Separating them is this tab. Skip it entirely if the client holds no brokerage account.
A5: THE THREE DOCUMENTS — none is optional
C6: Consolidated Form 1099 — ONE PER ACCOUNT | E6: The tax figures: dividends by box, realized gain/loss split short vs long, wash sales, foreign tax, and the year's fees
C7: The DECEMBER (year-end) statement | E7: The book figures and every tie below. ⚠ One statement can cover several accounts — its summary will say Managed(2) or similar
C8: Last year's FILED return | E8: The opening position: cumulative unrealized, the capital-loss pool, and last year's presentation
C9: 1099 version worked from: | E9: Check before filing whether a CORRECTED 1099 has been issued.
A11: THE FIVE TIES — all five pass, or the split below is a guess
B12: Check | C12: Account 1 | D12: Account 2 | E12: TOTAL — books | F12: Tie | G12: Statement says
B13: Account number (last 4)
B14: 1 · Beginning value at 31 Dec LAST year | E14: =N(C14)+N(D14) -> 0 | G14: Statement · Beginning Account Value, year-to-date
B15: 2 · Net deposits / withdrawals for the year | E15: =N(C15)+N(D15) -> 0 | G15: 🔎 NOT a tie — the PROOF of whether cash moved. Zero net means the whole change is performance. A transfer between the client's own accounts nets to zero across the pair
B16: 3 · Income year-to-date | E16: =N(C16)+N(D16) -> 0 | G16: Statement · Income YTD. Must equal the book Dividend Income account
B17: 4 · Fees year-to-date (enter POSITIVE) | E17: =N(C17)+N(D17) -> 0 | G17: Statement · Fees YTD. Must also equal the 1099's own fee schedule
B18: 5 · CHANGE IN INVESTMENT VALUE year-to-date | E18: =N(C18)+N(D18) -> 0 | G18: ⭐ The statement prints this. It is realized + unrealized combined — the figure the whole split runs off
B19: Ending value at 31 Dec THIS year | E19: =N(C19)+N(D19) -> 0 | G19: Statement · Ending Account Value. Use 'with accruals' if both are shown — and use the SAME convention every year
B20: Roll-forward: beginning + deposits + income − fees + change | C20: =N(C14)+N(C15)+N(C16)-N(C17)+N(C18) -> 0 | D20: =N(D14)+N(D15)+N(D16)-N(D17)+N(D18) -> 0 | E20: =N(E14)+N(E15)+N(E16)-N(E17)+N(E18) -> 0 | G20: Must equal the ending value, to the cent, per account AND in total.
B21: → does it equal the ending value? | C21: =IF(AND(N(C20)=0,N(C19)=0),"—",IF(ABS(N(C20)-N(C19))<0.005,"PASS","CHECK")) -> — | D21: =IF(AND(N(D20)=0,N(D19)=0),"—",IF(ABS(N(D20)-N(D19))<0.005,"PASS","CHECK")) -> — | E21: =IF(AND(N(E20)=0,N(E19)=0),"—",IF(ABS(N(E20)-N(E19))<0.005,"PASS","CHECK")) -> — | G21: A CHECK here, in order of likelihood: a month was never booked · a deposit went through the plug instead of being posted as a transfer · 'with accruals' mixed with 'without' between years · an entry posted to the wrong account of the pair.
B22: Books — Dividend Income account for the year | F22: =IF(AND(N(E22)=0,N(E16)=0),"—",IF(ABS(N(E22)-N(E16))<0.005,"PASS","CHECK")) -> — | G22: Tie 3.
B23: Books — fees account for the year | F23: =IF(AND(N(E23)=0,N(E17)=0),"—",IF(ABS(N(E23)-N(E17))<0.005,"PASS","CHECK")) -> — | G23: Tie 4. Also compare to the 1099's fee schedule.
B24: Books — Investment Income/Loss, parent AND every sub-account | F24: =IF(AND(N(E24)=0,N(E18)=0),"—",IF(ABS(N(E24)-N(E18))<0.005,"PASS","CHECK")) -> — | G24: Tie 5 — the important one. Add the parent and all children.
A26: THE SPLIT
B27: Change in investment value for the year | E27: =E18 -> 0
B28: less 1099-B NET realized gain / (loss), all accounts, short + long | G28: Also feeds Schedule D (tab 4). Enter a loss as a NEGATIVE.
B29: → UNREALIZED gain / (loss) for the year | E29: =E27-N(E28) -> 0 | G29: 🛑 Goes to Schedule M-1 (tab 9) — which line depends on the SIGN. Tab 9 decides it.
A31: THE CROSS-CHECK
B32: Cumulative unrealized at 1 January (tab 0) | E32: ='0-Client'!$C$25 -> 0
B33: plus this year's unrealized | E33: =E29 -> 0
B34: → expected cumulative at 31 December | E34: =E32+E33 -> 0
B35: Statement's own cumulative unrealized position at 31 December | G35: Enter the short-term and long-term parts below for tab 12.
B36: RESIDUAL | E36: =E35-E34 -> 0 | F36: =IF(N(E35)=0,"—",IF(ABS(E36)<MAX(100,ABS(E35)*0.005),"OK","CHECK")) -> — | G36: Tens or a few hundred dollars is the NORMAL residual — the statement excludes positions with no cost basis and omits wash sales from the last business day. Thousands is an error: go back to the five ties.
B37: of which short-term
B38: of which long-term
A40: THE ONE ENTRY TO POST, DATED 31 DECEMBER
B41: Net income does not move and the balance sheet is untouched. It exists so next year can READ the two figures instead of deriving them.
B42: Account | C42: Balance now | D42: Should be | E42: Debit | F42: Credit
B43: Investment Income/Loss (parent — REALIZED) | D43: =N(E28) -> 0 | E43: =IF(N(C43)>D43,N(C43)-D43,0) -> 0 | F43: =IF(N(C43)<D43,D43-N(C43),0) -> 0 | G43: Income accounts: a credit balance is positive.
B44: Investment Income/Loss : Unrealized Gain/Loss | D44: =E29 -> 0 | E44: =IF(N(C44)>D44,N(C44)-D44,0) -> 0 | F44: =IF(N(C44)<D44,D44-N(C44),0) -> 0
B45: Totals — must be equal | E45: =SUM(E43:E44) -> 0 | F45: =SUM(F43:F44) -> 0 | G45: =IF(AND(N(E45)=0,N(F45)=0),"—",IF(ABS(N(E45)-N(F45))<0.005,"PASS","CHECK")) -> —
...

Sheet 6-SchJ
A1: 6 · Schedule J — the tax, and what has been paid
A2: A C-corporation pays a FLAT 21% (§11(b)). Line numbers last verified against the 2024 forms · 2026-09-09. Re-verify on irs.gov before entering anything.
A4: THE TAX
B5: Line | D5: Amount | E5: Typed? | F5: Note
B6: — | C6: Taxable income (page 1 line 30) | D6: ='2-Page1'!$D$42 -> 0 | E6: computed | F6: Tab 2
B7: — | C7: Corporate rate | D7: 0.21 | E7: TYPED | F7: 21% since 2018. Re-verify each year — this is the one rate that would change everything.
B8: 2 | C8: Income tax | D8: =ROUND(MAX(0,D6)*D7,0) -> 0 | E8: computed | F8: Flat rate on taxable income
B9: 3 | C9: Base erosion minimum tax (Form 8991) | E9: TYPED | F9: Large corporations only — normally blank
B10: 4 | C10: Add lines 2 and 3 | D10: =D8+D9 -> 0 | E10: computed
B11: 5a | C11: Foreign tax credit (Form 1118) | E11: TYPED | F11: Or deduct the foreign tax instead — for a small amount, deduct
B12: 5b | C12: Credit from Form 8834 | E12: TYPED
B13: 5c | C13: General business credit (Form 3800) | E13: TYPED
B14: 5d | C14: Credit for prior year minimum tax (Form 8827) | E14: TYPED
B15: 5e | C15: Bond credits (Form 8912) | E15: TYPED
B16: 6 | C16: Total credits | D16: =SUM(D11:D15) -> 0 | E16: computed
B17: 7 | C17: Subtract line 6 from line 4 | D17: =MAX(0,D10-D16) -> 0 | E17: computed
B18: 8 | C18: Personal holding company tax (Schedule PH) | E18: TYPED
B19: 9 | C19: Other taxes and recaptures | E19: TYPED | F19: Recapture of investment credit, low-income housing, etc.
B20: 12 | C20: TOTAL TAX → page 1 line 31 | D20: =D17+D18+D19 -> 0 | E20: computed | F20: Verified against a filed 2024 return
A22: PAYMENTS AND REFUNDABLE CREDITS
B23: — | C23: Overpayment credited from last year | D23: =N('0-Client'!$C$29) -> 0 | E23: computed | F23: Tab 0
B24: — | C24: Estimated tax payments made during the year | D24: =N('0-Client'!$C$28) -> 0 | E24: computed | F24: Tab 0
B25: — | C25: Paid with an extension (Form 7004) | E25: TYPED
B26: — | C26: Backup withholding and other refundable credits | E26: TYPED
B27: 23 | C27: TOTAL PAYMENTS AND CREDITS → page 1 line 33 | D27: =SUM(D23:D26) -> 0 | E27: computed | F27: Verified against a filed 2024 return
C29: ⚠ Only lines 2, 12 and 23 were verified against a real filed 1120. The intermediate numbering on Schedule J moves — open the current-year form before entering anything in the middle block, and correct this sheet if it has changed.

Sheet 7-SchK
A1: 7 · Schedule K — the questions
A2: Answers change what else the return must carry. Line numbers last verified against the 2024 forms · 2026-09-09. Re-verify on irs.gov before entering anything.
A4: THE ONES THAT CHANGE THE RETURN
B5: Question | C5: Answer | D5: If this is the answer…
B6: Accounting method — cash, accrual, or other | D6: Must match the books AND the prior return. A change needs Form 3115
B7: Business activity code number | D7: Six digits, from the Form 1120 instructions. Must match what the company actually does
B8: Business activity / product or service | D8: Plain words, in ENGLISH, exactly as it should print
B9: Is the corporation a subsidiary in an affiliated group or a parent-subsidiary controlled group? | D9: Yes → name the parent and its EIN
B10: Did any individual or estate own 20% or more of the voting stock, directly or indirectly? | D10: Yes → Schedule G (Form 1120) is required
B11: Did any entity own 20% or more of the voting stock? | D11: Yes → Schedule G
B12: Did the corporation own 20% or more of any foreign or domestic corporation? | D12: Yes → the ownership schedule
B13: At any time during the year, did the corporation have an interest in or authority over a FOREIGN financial account? | D13: Yes → FinCEN Form 114 (FBAR) is due separately, and it is NOT part of the return
B14: Was the corporation the grantor of, or transferor to, a foreign trust? | D14: Yes → Form 3520
B15: Did the corporation receive a distribution from, or was it the owner of, a foreign entity? | D15: Yes → Form 5471 / 8865 / 8858 as applicable
B16: Total receipts AND total assets both under $250,000? | D16: Yes → Schedules L, M-1 and M-2 are not required (tab 0 computes this)
B17: Did the corporation make any payments requiring Form 1099? | D17: Yes → and were they filed? Both boxes get answered
... B20: Did the corporation dispose of an interest in a qualified opportunity fund? | D20: Yes → Form 8949 and the Schedule D question
B22: This is a working checklist of the questions that change what else the return carries — not the whole of Schedule K. Answer every question on the form itself.

Sheet 8-SchL
A1: 8 · Schedule L — balance sheet per books
A2: 🔑 The BEGINNING column is copied from last year's FILED return — never recalculated. Line numbers last verified against the 2024 forms · 2026-09-09. Re-verify on irs.gov before entering anything.
A4: ASSETS
B5: Line | C5: Concept | D5: Beginning of year | E5: End of year | F5: Note
B6: 1 | C6: Cash | F6: ⚠ CASH ONLY. A brokerage portfolio typed as a Bank account in QuickBooks lands here by default — it belongs on line 9
B7: 2a | C7: Trade notes and accounts receivable
B8: 2b | C8: Less allowance for bad debts | F8: Enter POSITIVE; it is subtracted below
B9: 3 | C9: Inventories
B10: 4 | C10: U.S. government obligations
B11: 5 | C11: Tax-exempt securities
B12: 6 | C12: Other current assets (attach statement)
B13: 7 | C13: Loans to shareholders | F13: A real balance here invites a below-market-interest question (§7872)
B14: 8 | C14: Mortgage and real estate loans
B15: 9 | C15: Other investments (attach statement) | F15: 🔴 THE BROKERAGE PORTFOLIO BELONGS HERE. Tab 5's ending value. No tax effect — but showing seven figures of equities as Cash misstates the balance sheet a lender reads
B16: 10a | C16: Buildings and other depreciable assets
B17: 10b | C17: Less accumulated depreciation | F17: Enter POSITIVE
B18: 11a | C18: Depletable assets
B19: 11b | C19: Less accumulated depletion | F19: Enter POSITIVE
B20: 12 | C20: Land
B21: 13a | C21: Intangible assets (amortizable only)
B22: 13b | C22: Less accumulated amortization | F22: Enter POSITIVE
B23: 14 | C23: Other assets (attach statement)
B24: 15 | C24: TOTAL ASSETS | D24: =SUM(D6:D7)-N(D8)+SUM(D9:D16)-N(D17)+D18-N(D19)+D20+D21-N(D22)+D23 -> 0 | E24: =SUM(E6:E7)-N(E8)+SUM(E9:E16)-N(E17)+E18-N(E19)+E20+E21-N(E22)+E23 -> 0
A26: LIABILITIES AND SHAREHOLDERS' EQUITY
B27: Line | C27: Concept | D27: Beginning of year | E27: End of year | F27: Note
B28: 16 | C28: Accounts payable
B29: 17 | C29: Mortgages, notes, bonds payable in less than 1 year
B30: 18 | C30: Other current liabilities (attach statement)
B31: 19 | C31: Loans from shareholders
B32: 20 | C32: Mortgages, notes, bonds payable in 1 year or more
B33: 21 | C33: Other liabilities (attach statement)
B34: 22a | C34: Capital stock — preferred
B35: 22b | C35: Capital stock — common
B36: 23 | C36: Additional paid-in capital
B37: 24 | C37: Retained earnings — appropriated
B38: 25 | C38: Retained earnings — unappropriated | D38: =N('0-Client'!$C$26) -> 0 | E38: ='10-SchM2'!$D$14 -> 0 | F38: Beginning = last year's FILED return (tab 0). Ending = Schedule M-2 line 8 (tab 10). Where the filed return and QuickBooks disagree, the RETURN governs — and the difference is written into the working paper so nobody re-derives it next year.
B39: 26 | C39: Adjustments to shareholders' equity
B40: 27 | C40: Less cost of treasury stock | F40: Enter POSITIVE
B41: 28 | C41: TOTAL LIABILITIES AND EQUITY | D41: =SUM(D28:D39)-N(D40) -> 0 | E41: =SUM(E28:E39)-N(E40) -> 0
C43: Does the balance sheet BALANCE? | D43: =IF(AND(N(D24)=0,N(D41)=0),"—",IF(ABS(N(D24)-N(D41))<0.005,"PASS","CHECK")) -> — | E43: =IF(AND(N(E24)=0,N(E41)=0),"—",IF(ABS(N(E24)-N(E41))<0.005,"PASS","CHECK")) -> — | F43: Both columns. A beginning column that does not balance means it was not copied from the filed return.
...

Sheet 9-SchM1
A1: 9 · Schedule M-1 — book income to taxable income
A2: 🛑 The unrealized figure's LINE depends on its SIGN, and the sign flips between years. This tab decides it for you.
A4: THE SIGN TRAP — enter ONE signed figure and let the sheet place it
C5: A book unrealized LOSS belongs on line 5; a book unrealized GAIN on line 7. A preparer copying last year's placement produces a return that balances internally and is wrong. Enter the figure once, signed, and do not place it by hand.
C6: Unrealized gain / (loss) for the year (tab 5) | D6: ='5-Investments'!$E$29 -> 0 | F6: A GAIN is positive, a LOSS negative. Tab 5 signs it correctly.
C7: → it belongs on | D7: =IF(N(D6)=0,"neither — no unrealized movement",IF(N(D6)>0,"LINE 7 — income on books not on the return","LINE 5 — expenses on books not deducted")) -> neither — no unrealized movement
A9: SCHEDULE M-1
B10: Line | C10: Concept | D10: Amount | E10: Typed? | F10: Note
B11: 1 | C11: Net income (loss) per books | E11: TYPED | F11: AFTER federal income tax. The whole company's book net income, not just the investment part
B12: 2 | C12: Federal income tax per books | D12: =SUMIF('1-TrialBalance'!$D$39:$D$118,"FED_TAX",'1-TrialBalance'!$C$39:$C$118) -> 0 | E12: computed | F12: Trial balance · FED_TAX
B13: 3 | C13: Excess of capital losses over capital gains | D13: ='4-SchD'!$F$35 -> 0 | E13: computed | F13: Tab 4 — the non-deductible capital loss, added back
B14: 4 | C14: Income subject to tax not recorded on books | E14: TYPED | F14: Rare
B15: 5 | C15: Expenses on books not deducted on this return:
B16: 5a | C16: Depreciation | E16: TYPED
B17: 5b | C17: Charitable contributions over the 10% limit | D17: ='2-Page1'!$D$56 -> 0 | E17: computed | F17: Tab 2 — the limit block
B18: 5c | C18: Travel and entertainment — the non-deductible half | E18: TYPED | F18: Meals are 50% disallowed; entertainment entirely
B19: 5d | C19: UNREALIZED LOSS on investments | D19: =IF(N(D6)<0,-N(D6),0) -> 0 | E19: computed | F19: 🛑 Populates ONLY when the year's unrealized movement is a LOSS
B20: 5e | C20: Other — itemize | E20: TYPED
B21: 5 | C21: Total of line 5 | D21: =SUM(D16:D20) -> 0
B22: 6 | C22: Add lines 1 through 5 | D22: =SUM(D11:D14)+D21 -> 0
B23: 7 | C23: Income on books not included on this return:
B24: 7a | C24: Tax-exempt interest | E24: TYPED
B25: 7b | C25: UNREALIZED GAIN on investments | D25: =IF(N(D6)>0,N(D6),0) -> 0 | E25: computed | F25: 🛑 Populates ONLY when the year's unrealized movement is a GAIN
B26: 7c | C26: Dividend income on books not on this return | D26: =N('5-Investments'!$E$53) -> 0 | E26: computed | F26: Tab 5 — book dividends less 1099 box 1a and box 2a. The books follow the statement, the return follows the 1099; the gap belongs HERE, not in a journal entry
B27: 7d | C27: Other — itemize | E27: TYPED
B28: 7 | C28: Total of line 7 | D28: =SUM(D24:D27) -> 0
B29: 8 | C29: Deductions on this return not charged against book income | E29: TYPED
B30: 9 | C30: Add lines 7 and 8 | D30: =D28+D29 -> 0
B31: 10 | C31: Income — line 6 less line 9 | D31: =D22-D30 -> 0 | F31: MUST equal page 1 line 28.
C32: Page 1 line 28 | D32: ='2-Page1'!$D$38 -> 0 | E32: =IF(AND(N(D31)=0,N(D32)=0),"—",IF(ABS(N(D31)-N(D32))<0.005,"PASS","CHECK")) -> — | F32: A CHECK here means one of the three investment items has the wrong sign.

Sheet 10-SchM2
A1: 10 · Schedule M-2 — unappropriated retained earnings
A2: Ties Schedule L line 25 from one year to the next. Line numbers last verified against the 2024 forms · 2026-09-09. Re-verify on irs.gov before entering anything.
B4: Line | C4: Concept | D4: Amount | E4: Typed? | F4: Note
B5: 1 | C5: Balance at beginning of year | D5: =N('0-Client'!$C$26) -> 0 | E5: from tab 0 | F5: 🔑 Last year's FILED return, Schedule L line 25 ending column — NOT QuickBooks.
B6: 2 | C6: Net income (loss) per books | D6: ='9-SchM1'!$D$11 -> 0 | E6: from tab 9 | F6: Same figure as Schedule M-1 line 1. If they differ, one of them is wrong.
B7: 3 | C7: Other increases — itemize | E7: TYPED | F7: Needs a statement.
B8: 4 | C8: Add lines 1, 2 and 3 | D8: =SUM(D5:D7) -> 0
B9: 5a | C9: Distributions — cash | E9: TYPED | F9: A C-corporation's distribution is a DIVIDEND to the shareholder to the extent of earnings and profits — and it needs a Form 1099-DIV. Enter POSITIVE.
B10: 5b | C10: Distributions — stock | E10: TYPED | F10: Enter POSITIVE.
B11: 5c | C11: Distributions — property | E11: TYPED | F11: Enter POSITIVE.
B12: 6 | C12: Other decreases — itemize | E12: TYPED | F12: Needs a statement. A separate 'Dividends Paid' equity account in QuickBooks usually lands here — which is why book retained earnings and the return's can legitimately differ.
B13: 7 | C13: Add lines 5 and 6 | D13: =SUM(D9:D12) -> 0
B14: 8 | C14: BALANCE AT END OF YEAR → Schedule L line 25 | D14: =D8-D13 -> 0 | F14: Tab 8 pulls this automatically.
C16: Retained earnings per QuickBooks at year end, for comparison | F16: They need not agree. When they do not, say WHY in the working paper — next year's beginning column is copied from this return, not from the books.
C17: Difference | D17: =D14-N(D16) -> 0

Sheet 11-TieOuts
A1: 11 · Tie-outs — every one must pass
A2: 🛑 Never file with a CHECK showing. A failed tie is a mapping error, not a rounding one.
B4: Check | C4: This | D4: must equal this | E4: Result | F4: If it fails
B5: Schedule M-1 line 10 = page 1 line 28 | C5: ='9-SchM1'!$D$31 -> 0 | D5: ='2-Page1'!$D$38 -> 0 | E5: =IF(AND(N(C5)=0,N(D5)=0),"—",IF(ABS(N(C5)-N(D5))<0.005,"PASS","CHECK")) -> — | F5: One of the M-1 items has the wrong sign — start with the unrealized figure.
B6: Schedule M-1 line 1 = Schedule M-2 line 2 | C6: ='9-SchM1'!$D$11 -> 0 | D6: ='10-SchM2'!$D$6 -> 0 | E6: =IF(AND(N(C6)=0,N(D6)=0),"—",IF(ABS(N(C6)-N(D6))<0.005,"PASS","CHECK")) -> — | F6: Both are 'net income per books'. They cannot differ.
B7: Schedule M-2 line 8 = Schedule L line 25, ending | C7: ='10-SchM2'!$D$14 -> 0 | D7: ='8-SchL'!$E$38 -> 0 | E7: =IF(AND(N(C7)=0,N(D7)=0),"—",IF(ABS(N(C7)-N(D7))<0.005,"PASS","CHECK")) -> — | F7: Tab 8 pulls this; a break means someone overtyped it.
B8: Schedule L balances — ENDING column | C8: ='8-SchL'!$E$24 -> 0 | D8: ='8-SchL'!$E$41 -> 0 | E8: =IF(AND(N(C8)=0,N(D8)=0),"—",IF(ABS(N(C8)-N(D8))<0.005,"PASS","CHECK")) -> — | F8: Assets ≠ liabilities + equity. Usually a missing account or a sign.
B9: Schedule L balances — BEGINNING column | C9: ='8-SchL'!$D$24 -> 0 | D9: ='8-SchL'!$D$41 -> 0 | E9: =IF(AND(N(C9)=0,N(D9)=0),"—",IF(ABS(N(C9)-N(D9))<0.005,"PASS","CHECK")) -> — | F9: The beginning column was not copied from last year's filed return.
B10: Schedule L beginning assets = last year's filed return | C10: ='8-SchL'!$D$24 -> 0 | D10: ='0-Client'!$C$27 -> 0 | E10: =IF(AND(N(C10)=0,N(D10)=0),"—",IF(ABS(N(C10)-N(D10))<0.005,"PASS","CHECK")) -> — | F10: Copy the filed return's ending column. Do not recalculate it from the books.
B11: Page 1 line 4 = Schedule C line 23 | C11: ='2-Page1'!$D$11 -> 0 | D11: ='3-SchC'!$D$42 -> 0 | E11: =IF(AND(N(C11)=0,N(D11)=0),"—",IF(ABS(N(C11)-N(D11))<0.005,"PASS","CHECK")) -> — | F11: Tab 2 pulls this automatically.
B12: Page 1 line 29b = Schedule C line 24 | C12: ='2-Page1'!$D$40 -> 0 | D12: ='3-SchC'!$F$43 -> 0 | E12: =IF(AND(N(C12)=0,N(D12)=0),"—",IF(ABS(N(C12)-N(D12))<0.005,"PASS","CHECK")) -> — | F12: Tab 2 pulls this automatically.
B13: Page 1 line 8 = Schedule D Part III line 18 | C13: ='2-Page1'!$D$15 -> 0 | D13: ='4-SchD'!$F$30 -> 0 | E13: =IF(AND(N(C13)=0,N(D13)=0),"—",IF(ABS(N(C13)-N(D13))<0.005,"PASS","CHECK")) -> — | F13: A net capital LOSS must arrive as zero — never as a negative.
B14: Page 1 line 31 = Schedule J total tax | C14: ='2-Page1'!$D$45 -> 0 | D14: ='6-SchJ'!$D$20 -> 0 | E14: =IF(AND(N(C14)=0,N(D14)=0),"—",IF(ABS(N(C14)-N(D14))<0.005,"PASS","CHECK")) -> — | F14: Tab 2 pulls this.
B15: Brokerage roll-forward = the statement's ending value | C15: ='5-Investments'!$E$20 -> 0 | D15: ='5-Investments'!$E$19 -> 0 | E15: =IF(AND(N(C15)=0,N(D15)=0),"—",IF(ABS(N(C15)-N(D15))<0.005,"PASS","CHECK")) -> — | F15: The five ties on tab 5 have not all passed. Fix the books before the split is used.
B16: Brokerage ending value = Schedule L line 9 (other investments) | C16: ='5-Investments'!$E$19 -> 0 | D16: ='8-SchL'!$E$15 -> 0 | E16: =IF(AND(N(C16)=0,N(D16)=0),"—",IF(ABS(N(C16)-N(D16))<0.005,"PASS","CHECK")) -> — | F16: Either the portfolio is still sitting in Schedule L line 1 Cash, or line 9 was not filled in.
A18: THINGS NO FORMULA CAN CHECK — read them and tick
C19: Every row on the trial balance has a map code, and the unmapped-amount counter on tab 1 reads zero.
C20: Schedule C: if the client holds domestic corporate shares, the broker was ASKED about §243/§854(b) eligibility, and the answer — whatever it was — is written down.
C21: Schedule C: where a DRD is being claimed, the §246(c) holding period was tested against the actual purchase dates, not assumed.
C22: The capital-loss pool on tab 4 has been carried to tab 12. Nothing on the filed return records it.
C23: Every 'attach statement' line with an amount actually HAS its statement drafted — Page 1 lines 10 and 26, Schedule L lines 6, 9, 14, 18, 21, and Schedule M-2 lines 3 and 6.
C24: No CORRECTED Form 1099 has arrived since the figures were taken.
C25: The accounting method on Schedule K matches both the books and the prior return.
C26: Every figure that changes the return was read off the CURRENT-year form on irs.gov, not from this workbook's line numbers.
C27: The working paper in projects/tax-returns/ has been written, with each decision, who made it, and the alternative not taken.

Sheet 12-CarryForward
A1: 12 · What next year needs from this year
A2: Fill this in BEFORE you close the file. Several of these appear nowhere on the filed return.
B4: Next year's preparer copies this block into tab 0 of a fresh workbook. Every line here is expensive to reconstruct and three of them cannot be reconstructed from the return at all.
B5: Item | C5: Amount / answer | D5: On the return? | E5: Why it matters
B6: Retained earnings at year end, PER THIS RETURN | C6: ='10-SchM2'!$D$14 -> 0 | D6: yes | E6: Schedule M-2 line 8. Becomes next year's M-2 line 1 and Schedule L beginning — never recalculated from the books
B7: Total assets at year end, PER THIS RETURN | C7: ='8-SchL'!$E$24 -> 0 | D7: yes | E7: Becomes next year's Schedule L beginning column
B8: CAPITAL-LOSS POOL carried forward | C8: ='4-SchD'!$F$40 -> 0 | D8: NO | E8: 🛑 Schedule D's carryover line is BLANK in a year with no gains. This workbook is the only record. Back 3 years, forward 5; short-term when used
B9: Earliest year in that pool | D9: NO | E9: Drives the 5-year expiry
B10: NOL carryforward remaining | D10: NO | E10: Post-2017 losses carry forward indefinitely but are capped at 80% of taxable income
B11: Charitable contributions carried forward | C11: ='2-Page1'!$D$56 -> 0 | D11: NO | E11: 5 years. The return shows the deduction taken, not the carryforward
B12: Cumulative unrealized gain/(loss) on investments | C12: ='5-Investments'!$E$35 -> 0 | D12: NO | E12: Next year's cross-check needs it. Nothing on the return carries it
B13: of which short-term | C13: ='5-Investments'!$E$37 -> 0 | D13: NO
B14: of which long-term | C14: ='5-Investments'!$E$38 -> 0 | D14: NO
B15: TAX COST BASIS of the portfolio | C15: ='5-Investments'!$E$54 -> 0 | D15: NO | E15: Book carrying value less cumulative unrealized — the figure that reconciles the balance sheet to the tax basis
B16: Cumulative return of capital received | D16: NO | E16: Reduces basis; nothing else records it
B17: Value convention used — 'with accruals' or 'without' | D17: NO | E17: Changing it between years silently breaks the roll-forward
B18: The DRD answer — who was asked, when, what they said | D18: partly | E18: An untaken deduction WITH a reason is a decision; without one it is next year's repeat
B19: Schedule L presentation of the portfolio — Cash or Other investments | D19: yes | E19: If it moved this year, next year's beginning column follows THIS return, not the one before
B20: Anything on this return that the BOOKS do not carry | D20: — | E20: So next year copies it instead of re-deriving it
A22: WHERE THIS ALSO HAS TO GO
B23: This workbook is a working file, not the firm's record. Copy the decisions, the alternatives not taken and every figure above into the client's working paper at projects/tax-returns/<client>/<year>-form-1120.md — that is the only place in the repo that holds client figures, and it is what the reviewer reads before the PDF.
